Workbook

Sheet Final Summary
A1: Description/Handset Model | B1: V48_SKD | C1: V92
A2: Previous Price | B2: 3425 | C2: 4017
A3: Current Price | B3: 3249 | C3: 3774
A4: Total Adjustment @ Per Handset | B4: =B2-B3 -> 176 | C4: =C2-C3 -> 243
A7: Dealer Name | B7: V48_SKD | F7: V92
B8: Commercial | D8: BPA | F8: Commercial | H8: BPA
B9: Qty. | C9: Adjustment Value | D9: Qty. | E9: Adjustment Value | F9: Qty. | G9: Adjustment Value | H9: Qty. | I9: Adjustment Value
A10: M/S BTB Telecom | B10: 12 | C10: 2112 | D10: 12 | E10: =D10*$B$4 -> 2112 | F10: 2 | G10: 486 | H10: 2 | I10: =H10*$C$4 -> 486
A11: Rahman Telecom | B11: 8 | C11: 1408 | D11: 8 | E11: =D11*$B$4 -> 1408 | F11: 9 | G11: 2187 | H11: 9 | I11: =H11*$C$4 -> 2187
A12: Swastidip Enterprise | B12: 20 | C12: 3520 | D12: 20 | E12: =D12*$B$4 -> 3520 | F12: 4 | G12: 972 | H12: 4 | I12: =H12*$C$4 -> 972
A13: Tulip Distribution | B13: 19 | C13: 3344 | D13: 19 | E13: =D13*$B$4 -> 3344 | F13: 9 | G13: 2187 | H13: 9 | I13: =H13*$C$4 -> 2187
A14: Grand Total | B14: 6733 | C14: =SUM(C10:C13) -> 10384 | D14: =SUM(D10:D13) -> 59 | E14: =SUM(E10:E13) -> 10384 | F14: 3683 | G14: =SUM(G10:G13) -> 5832 | H14: =SUM(H10:H13) -> 24 | I14: =SUM(I10:I13) -> 5832

Sheet Summary
B2: Model | C2: Adjustment/ Handset | D2: Qty. | E2: Adjusted Amount
C3: BDT | D3: Pcs. | E3: BDT
B4: ='Final Summary'!B1 -> V48_SKD | C4: ='Final Summary'!B4 -> 176 | D4: ='Final Summary'!D14 -> 59 | E4: ='Final Summary'!E14 -> 10384
B5: ='Final Summary'!C1 -> V92 | C5: ='Final Summary'!C4 -> 243 | D5: ='Final Summary'!H14 -> 24 | E5: ='Final Summary'!I14 -> 5832
B6: Total | D6: =SUM(D4:D5) -> 83 | E6: =SUM(E4:E5) -> 16216

Sheet Compiled
A1: EventTitle | B1: ClaimedRetailerID | C1: ClaimedRetailerName | D1: dealername | E1: ShortName
A2: Price adjustment of V48_SKD | B2: On Dealer | D2: Rahman Telecom | E2: V48_SKD
A3: Price adjustment of V48_SKD | B3: RET-08781 | C3: Rahman Telecom | D3: Rahman Telecom | E3: V48_SKD
A4: Price adjustment of V48_SKD | B4: RET-08781 | C4: Rahman Telecom | D4: Rahman Telecom | E4: V48_SKD
A5: Price adjustment of V48_SKD | B5: RET-08805 | C5: Rahman Telecom-2 | D5: Rahman Telecom | E5: V48_SKD
A6: Price adjustment of V48_SKD | B6: RET-08817 | C6: Afzal Telecom | D6: Rahman Telecom | E6: V48_SKD
A7: Price adjustment of V48_SKD | B7: RET-21143 | C7: Sweet Telecom | D7: Rahman Telecom | E7: V48_SKD
A8: Price adjustment of V48_SKD | B8: RET-12866 | C8: Sabbir Mobile Bazar | D8: Rahman Telecom | E8: V48_SKD
A9: Price adjustment of V48_SKD | B9: RET-12935 | C9: Rasel Telecom | D9: Rahman Telecom | E9: V48_SKD
A10: Price adjustment of V92 | B10: RET-08781 | C10: Rahman Telecom | D10: Rahman Telecom | E10: V92
A11: Price adjustment of V92 | B11: RET-29197 | C11: Brothers Shopping Center | D11: Rahman Telecom | E11: V92
A12: Price adjustment of V92 | B12: RET-08788 | C12: Khondokar Telecom | D12: Rahman Telecom | E12: V92
A13: Price adjustment of V92 | B13: RET-08794 | C13: Jononi Telecom | D13: Rahman Telecom | E13: V92
A14: Price adjustment of V92 | B14: RET-08805 | C14: Rahman Telecom-2 | D14: Rahman Telecom | E14: V92
A15: Price adjustment of V92 | B15: RET-08817 | C15: Afzal Telecom | D15: Rahman Telecom | E15: V92
A16: Price adjustment of V92 | B16: On Dealer | D16: Rahman Telecom | E16: V92
A17: Price adjustment of V92 | B17: RET-21144 | C17: Fahim Telecom | D17: Rahman Telecom | E17: V92
A18: Price adjustment of V92 | B18: RET-12937 | C18: Ray Electronics | D18: Rahman Telecom | E18: V92
A19: Price adjustment of V48_SKD | B19: On Dealer | D19: Swastidip Enterprise | E19: V48_SKD
A20: Price adjustment of V48_SKD | B20: On Dealer | D20: Swastidip Enterprise | E20: V48_SKD
A21: Price adjustment of V48_SKD | B21: On Dealer | D21: Swastidip Enterprise | E21: V48_SKD
A22: Price adjustment of V48_SKD | B22: On Dealer | D22: Swastidip Enterprise | E22: V48_SKD
A23: Price adjustment of V48_SKD | B23: On Dealer | D23: Swastidip Enterprise | E23: V48_SKD
A24: Price adjustment of V48_SKD | B24: On Dealer | D24: Swastidip Enterprise | E24: V48_SKD
A25: Price adjustment of V48_SKD | B25: On Dealer | D25: Swastidip Enterprise | E25: V48_SKD
A26: Price adjustment of V48_SKD | B26: On Dealer | D26: Swastidip Enterprise | E26: V48_SKD
A27: Price adjustment of V48_SKD | B27: On Dealer | D27: Swastidip Enterprise | E27: V48_SKD
A28: Price adjustment of V48_SKD | B28: RET-07767 | C28: Raiyan Electronics | D28: Swastidip Enterprise | E28: V48_SKD
A29: Price adjustment of V48_SKD | B29: RET-07775 | C29: Sopon Elect. | D29: Swastidip Enterprise | E29: V48_SKD
A30: Price adjustment of V48_SKD | B30: RET-07787 | C30: Raj Telecom | D30: Swastidip Enterprise | E30: V48_SKD
A31: Price adjustment of V48_SKD | B31: RET-07787 | C31: Raj Telecom | D31: Swastidip Enterprise | E31: V48_SKD
A32: Price adjustment of V48_SKD | B32: RET-07787 | C32: Raj Telecom | D32: Swastidip Enterprise | E32: V48_SKD
A33: Price adjustment of V48_SKD | B33: RET-07798 | C33: Continental | D33: Swastidip Enterprise | E33: V48_SKD
A34: Price adjustment of V48_SKD | B34: RET-07837 | C34: Touch Electronics | D34: Swastidip Enterprise | E34: V48_SKD
A35: Price adjustment of V48_SKD | B35: RET-07837 | C35: Touch Electronics | D35: Swastidip Enterprise | E35: V48_SKD
A36: Price adjustment of V48_SKD | B36: RET-11800 | C36: Bondhu Telecom | D36: Swastidip Enterprise | E36: V48_SKD
A37: Price adjustment of V48_SKD | B37: RET-11720 | C37: Tanvir Telecom | D37: Swastidip Enterprise | E37: V48_SKD
A38: Price adjustment of V48_SKD | B38: RET-19045 | C38: Aziz & Sons | D38: Swastidip Enterprise | E38: V48_SKD
A39: Price adjustment of V92 | B39: On Dealer | D39: Swastidip Enterprise | E39: V92
A40: Price adjustment of V92 | B40: RET-07767 | C40: Raiyan Electronics | D40: Swastidip Enterprise | E40: V92
...

Sheet Raw File
A1: EventTitle | B1: FromDate | C1: ClaimedRetailerID | D1: ClaimedRetailerName | E1: dealername | F1: ShortName
A2: Price adjustment of V48_SKD | B2: 2/15/2019 12:00:00 AM | C2: RET-07845 | D2: Mobile Park | E2: M/S BTB Telecom | F2: V48_SKD
A3: Price adjustment of V48_SKD | B3: 2/15/2019 12:00:00 AM | C3: RET-07855 | D3: Bina Mobile Center | E3: M/S BTB Telecom | F3: V48_SKD
A4: Price adjustment of V48_SKD | B4: 2/15/2019 12:00:00 AM | C4: RET-07856 | D4: Desh Telecom | E4: M/S BTB Telecom | F4: V48_SKD
A5: Price adjustment of V48_SKD | B5: 2/15/2019 12:00:00 AM | C5: RET-07858 | D5: Tuhin Mobile center | E5: M/S BTB Telecom | F5: V48_SKD
A6: Price adjustment of V48_SKD | B6: 2/15/2019 12:00:00 AM | C6: RET-07868 | D6: S.N Mobile Center | E6: M/S BTB Telecom | F6: V48_SKD
A7: Price adjustment of V48_SKD | B7: 2/15/2019 12:00:00 AM | C7: On Dealer | E7: M/S BTB Telecom | F7: V48_SKD
A8: Price adjustment of V48_SKD | B8: 2/15/2019 12:00:00 AM | C8: RET-07877 | D8: Mollah Mobile Center | E8: M/S BTB Telecom | F8: V48_SKD
A9: Price adjustment of V48_SKD | B9: 2/15/2019 12:00:00 AM | C9: RET-07912 | D9: Apurbo Electronics | E9: M/S BTB Telecom | F9: V48_SKD
A10: Price adjustment of V48_SKD | B10: 2/15/2019 12:00:00 AM | C10: RET-07918 | D10: Dighi Telecom | E10: M/S BTB Telecom | F10: V48_SKD
A11: Price adjustment of V48_SKD | B11: 2/15/2019 12:00:00 AM | C11: RET-07943 | D11: Friends Mobile Collection | E11: M/S BTB Telecom | F11: V48_SKD
A12: Price adjustment of V48_SKD | B12: 2/15/2019 12:00:00 AM | C12: RET-07918 | D12: Dighi Telecom | E12: M/S BTB Telecom | F12: V48_SKD
A13: Price adjustment of V48_SKD | B13: 2/15/2019 12:00:00 AM | C13: RET-29330 | D13: Natore Telecom | E13: M/S BTB Telecom | F13: V48_SKD
A14: Price adjustment of V92 | B14: 2/15/2019 12:00:00 AM | C14: RET-07845 | D14: Mobile Park | E14: M/S BTB Telecom | F14: V92
A15: Price adjustment of V92 | B15: 2/15/2019 12:00:00 AM | C15: RET-07918 | D15: Dighi Telecom | E15: M/S BTB Telecom | F15: V92
A16: Price adjustment of V48_SKD | B16: 2/15/2019 12:00:00 AM | C16: RET-08781 | D16: Rahman Telecom | E16: Rahman Telecom | F16: V48_SKD
A17: Price adjustment of V48_SKD | B17: 2/15/2019 12:00:00 AM | C17: RET-08781 | D17: Rahman Telecom | E17: Rahman Telecom | F17: V48_SKD
A18: Price adjustment of V48_SKD | B18: 2/15/2019 12:00:00 AM | C18: On Dealer | E18: Rahman Telecom | F18: V48_SKD
A19: Price adjustment of V48_SKD | B19: 2/15/2019 12:00:00 AM | C19: RET-08805 | D19: Rahman Telecom-2 | E19: Rahman Telecom | F19: V48_SKD
A20: Price adjustment of V48_SKD | B20: 2/15/2019 12:00:00 AM | C20: RET-08817 | D20: Afzal Telecom | E20: Rahman Telecom | F20: V48_SKD
A21: Price adjustment of V48_SKD | B21: 2/15/2019 12:00:00 AM | C21: RET-21143 | D21: Sweet Telecom | E21: Rahman Telecom | F21: V48_SKD
A22: Price adjustment of V48_SKD | B22: 2/15/2019 12:00:00 AM | C22: RET-12866 | D22: Sabbir Mobile Bazar | E22: Rahman Telecom | F22: V48_SKD
A23: Price adjustment of V48_SKD | B23: 2/15/2019 12:00:00 AM | C23: RET-12935 | D23: Rasel Telecom | E23: Rahman Telecom | F23: V48_SKD
A24: Price adjustment of V92 | B24: 2/15/2019 12:00:00 AM | C24: RET-08788 | D24: Khondokar Telecom | E24: Rahman Telecom | F24: V92
A25: Price adjustment of V92 | B25: 2/15/2019 12:00:00 AM | C25: RET-08794 | D25: Jononi Telecom | E25: Rahman Telecom | F25: V92
A26: Price adjustment of V92 | B26: 2/15/2019 12:00:00 AM | C26: RET-08805 | D26: Rahman Telecom-2 | E26: Rahman Telecom | F26: V92
A27: Price adjustment of V92 | B27: 2/15/2019 12:00:00 AM | C27: RET-08781 | D27: Rahman Telecom | E27: Rahman Telecom | F27: V92
A28: Price adjustment of V92 | B28: 2/15/2019 12:00:00 AM | C28: RET-08817 | D28: Afzal Telecom | E28: Rahman Telecom | F28: V92
A29: Price adjustment of V92 | B29: 2/15/2019 12:00:00 AM | C29: On Dealer | E29: Rahman Telecom | F29: V92
A30: Price adjustment of V92 | B30: 2/15/2019 12:00:00 AM | C30: RET-21144 | D30: Fahim Telecom | E30: Rahman Telecom | F30: V92
A31: Price adjustment of V92 | B31: 2/15/2019 12:00:00 AM | C31: RET-29197 | D31: Brothers Shopping Center | E31: Rahman Telecom | F31: V92
A32: Price adjustment of V92 | B32: 2/15/2019 12:00:00 AM | C32: RET-12937 | D32: Ray Electronics | E32: Rahman Telecom | F32: V92
A33: Price adjustment of V48_SKD | B33: 2/15/2019 12:00:00 AM | C33: On Dealer | E33: Swastidip Enterprise | F33: V48_SKD
A34: Price adjustment of V48_SKD | B34: 2/15/2019 12:00:00 AM | C34: On Dealer | E34: Swastidip Enterprise | F34: V48_SKD
A35: Price adjustment of V48_SKD | B35: 2/15/2019 12:00:00 AM | C35: On Dealer | E35: Swastidip Enterprise | F35: V48_SKD
A36: Price adjustment of V48_SKD | B36: 2/15/2019 12:00:00 AM | C36: On Dealer | E36: Swastidip Enterprise | F36: V48_SKD
A37: Price adjustment of V48_SKD | B37: 2/15/2019 12:00:00 AM | C37: On Dealer | E37: Swastidip Enterprise | F37: V48_SKD
A38: Price adjustment of V48_SKD | B38: 2/15/2019 12:00:00 AM | C38: RET-07767 | D38: Raiyan Electronics | E38: Swastidip Enterprise | F38: V48_SKD
A39: Price adjustment of V48_SKD | B39: 2/15/2019 12:00:00 AM | C39: RET-07775 | D39: Sopon Elect. | E39: Swastidip Enterprise | F39: V48_SKD
A40: Price adjustment of V48_SKD | B40: 2/15/2019 12:00:00 AM | C40: On Dealer | E40: Swastidip Enterprise | F40: V48_SKD
...
